Workbook

Sheet LEIA-ME
A1: Análise das Demonstrações Financeiras — Netflix, Inc. (NFLX) · ECO057
A2: Período: 2019T1 a 2026T2 (30 trimestres) · Valores em US$ milhões, salvo indicação.
A4: Como ler esta planilha
A5: • Números em AZUL são dados oficiais (insumos). Números em PRETO são fórmulas — clique na célula para ver o cálculo.
A6: • Linhas verdes são conferências: devem dar zero. O resumo está na aba Validacao.
A7: • "n.d." = não disponível (ex.: indicador LTM precisa de 4 trimestres; AH homóloga precisa do mesmo trimestre do ano anterior).
A9: Abas (ordem sugerida para a apresentação)
A10: 1. Macro e Setor — contexto: juros, inflação, câmbio e a situação dos concorrentes de streaming.
A11: 2. DRE, BP, DFC — demonstrações montadas a partir dos 10-Q/10-K, com conferência contra os totais informados à SEC.
A12: 3. AV — análise vertical (base: receita na DRE e ativo total no BP).
A13: 4. AH e AH_Anual — análise horizontal sequencial (t vs t−1), homóloga (t vs t−4), base fixa e anual.
A14: 5. Indicadores — margens, DuPont (ROA/ROE), liquidez, Fleuriet (CCL/NCG/ST), endividamento, GAO/GAF/GAT.
... A31: • O lucro de 2026T1 é explicado pela multa rescisória da WBD (US$ 2,8 bi) — e não por "créditos fiscais", como constava antes.

Sheet Graficos
A1: Gráficos da análise (atualizam com as fórmulas)
A2: Eixo X: trimestres · Um único eixo Y por gráfico, com unidade no título do eixo.

Sheet DRE
A1: Netflix, Inc. — Demonstração do Resultado (trimestral)
A2: US$ milhões · Fonte: SEC EDGAR, 10-Q e 10-K (XBRL). 4º tri = ano (10-K) − 9 meses (10-Q).
A4: Conta / indicador | B4: Fonte ou fórmula | C4: 2019T1 | D4: 2019T2 | E4: 2019T3 | F4: 2019T4 | G4: 2020T1 | H4: 2020T2 | I4: 2020T3 | J4: 2020T4 | K4: 2021T1 | L4: 2021T2 | M4: 2021T3 | N4: 2021T4 | O4: 2022T1 | P4: 2022T2 | Q4: 2022T3 | R4: 2022T4 | S4: 2023T1 | T4: 2023T2 | U4: 2023T3 | V4: 2023T4 | W4: 2024T1 | X4: 2024T2 | Y4: 2024T3 | Z4: 2024T4 | AA4: 2025T1 | AB4: 2025T2 | AC4: 2025T3 | AD4: 2025T4 | AE4: 2026T1 | AF4: 2026T2
A6: Demonstração do resultado
A7: (=) Receita líquida | B7: us-gaap:Revenues | C7: 4520.992 | D7: 4923.116 | E7: 5244.905 | F7: 5467.434 | G7: 5767.691 | H7: 6148.286 | I7: 6435.637 | J7: 6644.442 | K7: 7163.282 | L7: 7341.777 | M7: 7483.467 | N7: 7709.318 | O7: 7867.767 | P7: 7970.141 | Q7: 7925.589 | R7: 7852.053 | S7: 8161.503 | T7: 8187.301 | U7: 8541.668 | V7: 8832.825 | W7: 9370.44 | X7: 9559.31 | Y7: 9824.703 | Z7: 10246.513 | AA7: 10542.801 | AB7: 11079.166 | AC7: 11510.307 | AD7: 12050.762 | AE7: 12249.757 | AF7: 12559.938
A8: (−) Custo dos serviços (inclui amortização de conteúdo) | B8: us-gaap:CostOfRevenue | C8: 2870.614 | D8: 3005.657 | E8: 3097.919 | F8: 3466.023 | G8: 3599.701 | H8: 3643.707 | I8: 3867.751 | J8: 4165.16 | K8: 3868.511 | L8: 4018.008 | M8: 4206.589 | N8: 5239.575 | O8: 4284.705 | P8: 4690.755 | Q8: 4788.665 | R8: 5404.16 | S8: 4803.625 | T8: 4673.47 | U8: 4930.788 | V8: 5307.485 | W8: 4977.073 | X8: 5174.143 | Y8: 5119.884 | Z8: 5767.364 | AA8: 5263.147 | AB8: 5325.311 | AC8: 6164.25 | AD8: 6522.621 | AE8: 5888.238 | AF8: 6036.965
A9: (=) Lucro bruto | B9: Receita − Custo | C9: =C7-C8 -> 1650.378 | D9: =D7-D8 -> 1917.459 | E9: =E7-E8 -> 2146.986 | F9: =F7-F8 -> 2001.411 | G9: =G7-G8 -> 2167.99 | H9: =H7-H8 -> 2504.579 | I9: =I7-I8 -> 2567.886 | J9: =J7-J8 -> 2479.282 | ... AF9: =AF7-AF8 -> 6522.973
A10: (−) Marketing | B10: SellingAndMarketing / Marketing | C10: 616.578 | D10: 603.15 | E10: 553.797 | F10: 878.937 | G10: 503.83 | H10: 434.37 | I10: 527.597 | J10: 762.565 | K10: 512.512 | L10: 603.973 | M10: 635.948 | N10: 792.713 | O10: 555.978 | P10: 574.96 | Q10: 567.954 | R10: 831.61 | S10: 555.362 | T10: 627.168 | U10: 558.736 | V10: 916.617 | W10: 654.34 | X10: 644.084 | Y10: 642.926 | Z10: 976.204 | AA10: 688.37 | AB10: 713.265 | AC10: 786.295 | AD10: 1113.376 | AE10: 842.217 | AF10: 823.838
A11: (−) Tecnologia e desenvolvimento | B11: T&D / ResearchAndDevelopment | C11: 372.764 | D11: 383.233 | E11: 379.776 | F11: 409.376 | G11: 453.817 | H11: 435.045 | I11: 453.802 | J11: 486.936 | K11: 525.207 | L11: 537.321 | M11: 563.887 | N11: 647.47 | O11: 657.53 | P11: 716.846 | Q11: 662.739 | R11: 673.926 | S11: 687.275 | T11: 657.983 | U11: 657.159 | V11: 673.341 | W11: 702.473 | X11: 711.254 | Y11: 735.063 | Z11: 776.505 | AA11: 822.823 | AB11: 824.683 | AC11: 853.584 | AD11: 890.3 | AE11: 959.696 | AF11: 1007.675
A12: (−) Gerais e administrativas | B12: GeneralAndAdministrative | C12: 201.952 | D12: 224.657 | E12: 233.174 | F12: 254.586 | G12: 252.087 | H12: 277.236 | I12: 271.624 | J12: 275.539 | K12: 297.196 | L12: 334.845 | M12: 321.79 | N12: 397.79 | O12: 397.928 | P12: 409.297 | Q12: 373.213 | R12: 392.453 | S12: 400.924 | T12: 401.497 | U12: 478.591 | V12: 439.273 | W12: 404.02 | X12: 426.992 | Y12: 417.353 | Z12: 453.674 | AA12: 421.462 | AB12: 441.213 | AC12: 457.931 | AD12: 567.802 | AE12: 602.609 | AF12: 498.85
A13: (=) Despesas operacionais | B13: Soma | C13: =C10+C11+C12 -> 1191.294 | D13: =D10+D11+D12 -> 1211.04 | E13: =E10+E11+E12 -> 1166.747 | F13: =F10+F11+F12 -> 1542.899 | G13: =G10+G11+G12 -> 1209.734 | H13: =H10+H11+H12 -> 1146.651 | I13: =I10+I11+I12 -> 1253.023 | J13: =J10+J11+J12 -> 1525.04 | ... AF13: =AF10+AF11+AF12 -> 2330.363
A14: (=) Lucro operacional (EBIT / LAJIR) | B14: Lucro bruto − Desp. operacionais | C14: =C9-C13 -> 459.084 | D14: =D9-D13 -> 706.419 | E14: =E9-E13 -> 980.239 | F14: =F9-F13 -> 458.512 | G14: =G9-G13 -> 958.256 | H14: =H9-H13 -> 1357.928 | I14: =I9-I13 -> 1314.863 | J14: =J9-J13 -> 954.242 | ... AF14: =AF9-AF13 -> 4192.61
A15: (−) Despesa de juros | B15: InterestExpense(Nonoperating) | C15: 135.529 | D15: 152.033 | E15: 160.66 | F15: 177.801 | G15: 184.083 | H15: 189.151 | I15: 197.079 | J15: 197.186 | K15: 194.44 | L15: 191.322 | M15: 190.429 | N15: 189.429 | O15: 187.579 | P15: 175.455 | Q15: 172.575 | R15: 170.603 | S15: 174.239 | T15: 174.812 | U15: 175.563 | V15: 175.212 | W15: 173.314 | X15: 167.986 | Y15: 184.83 | Z15: 192.603 | AA15: 184.172 | AB15: 182.649 | AC15: 175.294 | AD15: 234.395 | AE15: 262.077 | AF15: 175.685
A16: (+/−) Juros e outras receitas/despesas (inclui câmbio) | B16: NonoperatingIncomeExpense | C16: 76.104 | D16: -53.47 | E16: 192.744 | F16: -131.378 | G16: 21.697 | H16: -133.175 | I16: -256.324 | J16: -250.639 | K16: 269.086 | L16: -62.519 | M16: 96.135 | N16: 108.512 | O16: 195.645 | P16: 220.226 | Q16: 261.404 | R16: -339.965 | S16: -71.204 | T16: 26.961 | U16: 168.218 | V16: -172.747 | W16: 155.359 | X16: 79.005 | Y16: -21.693 | Z16: 54.105 | AA16: 50.899 | AB16: 39.63 | AC16: 36.457 | AD16: 45.473 | AE16: 2852.166 | AF16: 51.661
A17: (=) Lucro antes do IR (LAIR) | B17: EBIT − Juros + Outras | C17: =C14-C15+C16 -> 399.659 | D17: =D14-D15+D16 -> 500.916 | E17: =E14-E15+E16 -> 1012.323 | F17: =F14-F15+F16 -> 149.333 | G17: =G14-G15+G16 -> 795.87 | H17: =H14-H15+H16 -> 1035.602 | I17: =I14-I15+I16 -> 861.46 | J17: =J14-J15+J16 -> 506.417 | ... AF17: =AF14-AF15+AF16 -> 4068.586
A18: (−) Imposto de renda (sinal original; benefício = negativo) | B18: IncomeTaxExpenseBenefit | C18: 55.607 | D18: 230.266 | E18: 347.079 | F18: -437.637 | G18: 86.803 | H18: 315.406 | I18: 71.484 | J18: -35.739 | K18: 327.787 | L18: 240.776 | M18: 211.888 | N18: -56.576 | O18: 382.245 | P18: 182.103 | Q18: 223.605 | R18: -15.948 | S18: 163.754 | T18: 191.722 | U18: 231.627 | V18: 210.312 | W18: 282.37 | X18: 366.55 | Y18: 339.445 | Z18: 265.661 | AA18: 323.375 | AB18: 506.262 | AC18: 562.494 | AD18: 349.22 | AE18: 1264.295 | AF18: 667.172
A19: (=) Lucro líquido | B19: LAIR − IR | C19: =C17-C18 -> 344.052 | D19: =D17-D18 -> 270.65 | E19: =E17-E18 -> 665.244 | F19: =F17-F18 -> 586.97 | G19: =G17-G18 -> 709.067 | H19: =H17-H18 -> 720.196 | I19: =I17-I18 -> 789.976 | J19: =J17-J18 -> 542.156 | ... AF19: =AF17-AF18 -> 3401.414
A21: Conferência com os valores informados à SEC (deve dar zero)
A22: EBIT calculado − EBIT informado | B22: OperatingIncomeLoss | C22: =C14-459.084 -> 0 | D22: =D14-706.419 -> 0 | E22: =E14-980.239 -> 0 | F22: =F14-458.512 -> 0 | G22: =G14-958.256 -> 0 | H22: =H14-1357.928 -> 0 | I22: =I14-1314.863 -> 0 | J22: =J14-954.242 -> 0 | K22: =K14-1959.856 -> 0 | L22: =L14-1847.63 -> 0 | M22: =M14-1755.253 -> 0 | N22: =N14-631.77 -> 0 | O22: =O14-1971.626 -> 0 | P22: =P14-1578.283 -> 0 | Q22: =Q14-1533.018 -> 0 | R22: =R14-549.904 -> 0 | S22: =S14-1714.317 -> 0 | T22: =T14-1827.183 -> 0 | U22: =U14-1916.394 -> 0 | V22: =V14-1496.109 -> 0 | W22: =W14-2632.534 -> 0 | X22: =X14-2602.837 -> 0 | Y22: =Y14-2909.477 -> 0 | Z22: =Z14-2272.766 -> 0 | AA22: =AA14-3346.999 -> 0 | AB22: =AB14-3774.694 -> 0 | AC22: =AC14-3248.247 -> 0 | AD22: =AD14-2956.663 -> 0 | AE22: =AE14-3956.997 -> 0 | AF22: =AF14-4192.61 -> 0
A23: LAIR calculado − LAIR informado | B23: IncomeBeforeIncomeTaxes | C23: =C17-399.659 -> 0 | D23: =D17-500.916 -> 0 | E23: =E17-1012.323 -> 0 | F23: =F17-149.333 -> 0 | G23: =G17-795.87 -> 0 | H23: =H17-1035.602 -> 0 | I23: =I17-861.46 -> 0 | J23: =J17-506.417 -> 0 | K23: =K17-2034.502 -> 0 | L23: =L17-1593.789 -> 0 | M23: =M17-1660.959 -> 0 | N23: =N17-550.853 -> 0 | O23: =O17-1979.692 -> 0 | P23: =P17-1623.054 -> 0 | Q23: =Q17-1621.847 -> 0 | R23: =R17-39.336 -> 0 | S23: =S17-1468.874 -> 0 | T23: =T17-1679.332 -> 0 | U23: =U17-1909.049 -> 0 | V23: =V17-1148.15 -> 0 | W23: =W17-2614.579 -> 0 | X23: =X17-2513.856 -> 0 | Y23: =Y17-2702.954 -> 0 | Z23: =Z17-2134.268 -> 0 | AA23: =AA17-3213.726 -> 0 | AB23: =AB17-3631.675 -> 0 | AC23: =AC17-3109.41 -> 0 | AD23: =AD17-2767.741 -> 0 | AE23: =AE17-6547.086 -> 0 | AF23: =AF17-4068.586 -> 0
A24: Lucro líquido calculado − informado | B24: NetIncomeLoss | C24: =C19-344.052 -> 0 | D24: =D19-270.65 -> 0 | E24: =E19-665.244 -> 0 | F24: =F19-586.97 -> 0 | G24: =G19-709.067 -> 0 | H24: =H19-720.196 -> 0 | I24: =I19-789.976 -> 0 | J24: =J19-542.156 -> 0 | K24: =K19-1706.715 -> 0 | L24: =L19-1353.013 -> 0 | M24: =M19-1449.071 -> 0 | N24: =N19-607.429 -> 0 | O24: =O19-1597.447 -> 0 | P24: =P19-1440.951 -> 0 | Q24: =Q19-1398.242 -> 0 | R24: =R19-55.284 -> 0 | S24: =S19-1305.12 -> 0 | T24: =T19-1487.61 -> 0 | U24: =U19-1677.422 -> 0 | V24: =V19-937.838 -> 0 | W24: =W19-2332.209 -> 0 | X24: =X19-2147.306 -> 0 | Y24: =Y19-2363.509 -> 0 | Z24: =Z19-1868.607 -> 0 | AA24: =AA19-2890.351 -> 0 | AB24: =AB19-3125.413 -> 0 | AC24: =AC19-2546.916 -> 0 | AD24: =AD19-2418.521 -> 0 | AE24: =AE19-5282.791 -> 0 | AF24: =AF19-3401.414 -> 0
A26: Itens de memória
A27: Ganho (perda) cambial — incluso em "outras" | B27: ForeignCurrencyTransactionGainLoss | C27: 57.6 | D27: -61.284 | E27: 171.36 | F27: -122.1 | G27: 93.06 | H27: -119.161 | I27: -249.194 | J27: -257.983 | K27: 253.33 | L27: -63.074 | M27: 136.488 | N27: 103.917 | O27: 161.821 | P27: 304.513 | Q27: 348.458 | R27: -461.681 | S27: -80.651 | T27: -28.952 | U27: 172.678 | V27: -239.371 | W27: 130.801 | X27: 42.692 | Y27: -104.809 | Z27: 52.855 | AA27: -28.547 | AB27: -55.238 | AC27: 1.707 | AD27: 9.73 | AE27: 10.11 | AF27: 8.813
A28: Amortização de conteúdo — inclusa no custo | B28: nflx:CostofServicesAmortization... | C28: 2124.686 | D28: 2231.915 | E28: 2279.977 | F28: 2579.669 | G28: 2483.385 | H28: 2607.159 | I28: 2733.743 | J28: 2982.625 | K28: 2719.196 | L28: 2806.803 | M28: 2963.051 | N28: 3741.317 | O28: 3166.365 | P28: 3261.348 | Q28: 3653.592 | R28: 3944.827 | S28: 3459.984 | T28: 3410.021 | U28: 3573.353 | V28: 3754.079 | W28: 3670.805 | X28: 3769.69 | Y28: 3699.521 | Z28: 4161.501 | AA28: 3823.112 | AB28: 3832.074 | AC28: 4002.744 | AD28: 4764.236 | AE28: 4217.9 | AF28: 4311.309
A29: Depreciação e amortização (imobilizado e intangíveis) | B29: DepreciationDepletionAndAmortization | C29: 23.561 | D29: 25.496 | E29: 26.704 | F29: 27.818 | G29: 28.517 | H29: 26.661 | I29: 28.589 | J29: 31.943 | K29: 35.741 | L29: 38.434 | M29: 70.253 | N29: 63.984 | O29: 74.602 | P29: 83.505 | Q29: 85.188 | R29: 93.387 | S29: 90.335 | T29: 89.385 | U29: 90.66 | V29: 86.567 | W29: 87.234 | X29: 81.227 | Y29: 80.914 | Z29: 79.539 | AA29: 80.067 | AB29: 80.013 | AC29: 87.326 | AD29: 85.983 | AE29: 98.575 | AF29: 100.53
A30: (=) EBITDA (EBIT + D&A; conteúdo NÃO é somado de volta) | B30: EBIT + D&A | C30: =C14+C29 -> 482.645 | D30: =D14+D29 -> 731.915 | E30: =E14+E29 -> 1006.943 | F30: =F14+F29 -> 486.33 | G30: =G14+G29 -> 986.773 | H30: =H14+H29 -> 1384.589 | I30: =I14+I29 -> 1343.452 | J30: =J14+J29 -> 986.185 | ... AF30: =AF14+AF29 -> 4293.14
A32: Na Netflix a amortização de conteúdo é custo operacional recorrente (substitui o "estoque" de filmes e séries); por isso não é adicionada ao EBITDA.

Sheet BP
A1: Netflix, Inc. — Balanço Patrimonial (fim de cada trimestre)
A2: US$ milhões · Fonte: SEC EDGAR, 10-Q e 10-K (XBRL).
A4: Conta / indicador | B4: Fonte ou fórmula | C4: 2019T1 | D4: 2019T2 | E4: 2019T3 | F4: 2019T4 | G4: 2020T1 | H4: 2020T2 | I4: 2020T3 | J4: 2020T4 | K4: 2021T1 | L4: 2021T2 | M4: 2021T3 | N4: 2021T4 | O4: 2022T1 | P4: 2022T2 | Q4: 2022T3 | R4: 2022T4 | S4: 2023T1 | T4: 2023T2 | U4: 2023T3 | V4: 2023T4 | W4: 2024T1 | X4: 2024T2 | Y4: 2024T3 | Z4: 2024T4 | AA4: 2025T1 | AB4: 2025T2 | AC4: 2025T3 | AD4: 2025T4 | AE4: 2026T1 | AF4: 2026T2
A6: Ativo
A7: Caixa e equivalentes | B7: CashAndCashEquivalents | C7: 3348.557 | D7: 5004.247 | E7: 4435.018 | F7: 5018.437 | G7: 5151.884 | H7: 7153.248 | I7: 8392.391 | J7: 8205.55 | K7: 8403.705 | L7: 7777.53 | M7: 7526.681 | N7: 6027.804 | O7: 6008.946 | P7: 5819.449 | Q7: 6113.733 | R7: 5147.176 | S7: 6714.594 | T7: 7662.788 | U7: 7353.245 | V7: 7116.913 | W7: 7024.766 | X7: 6624.939 | Y7: 7457.025 | Z7: 7804.733 | AA7: 7199.848 | AB7: 8177.405 | AC7: 9287.287 | AD7: 9033.681 | AE7: 12259.772 | AF7: 9099.232
A8: Aplicações financeiras de curto prazo | B8: ShortTermInvestments | C8: 0 | D8: 0 | E8: 0 | F8: 0 | G8: 0 | H8: 0 | I8: 0 | J8: 0 | K8: 0 | L8: 0 | M8: 0 | N8: 0 | O8: 0 | P8: 0 | Q8: 0 | R8: 911.276 | S8: 1112.91 | T8: 914.201 | U8: 514.201 | V8: 20.973 | W8: 20.973 | X8: 30.973 | Y8: 1766.902 | Z8: 1779.006 | AA8: 1171.142 | AB8: 213.115 | AC8: 37.105 | AD8: 28.678 | AE8: 28.678 | AF8: 28.678
A9: Outros ativos circulantes (recebíveis, adiantamentos) | B9: OtherAssetsCurrent | C9: 820.35 | D9: 872.91 | E9: 892.74 | F9: 1160.067 | G9: 1295.897 | H9: 1410.891 | I9: 1434.089 | J9: 1556.03 | K9: 1703.803 | L9: 1826.746 | M9: 1889.106 | N9: 2042.021 | O9: 2089.069 | P9: 2021.329 | Q9: 2703.17 | R9: 3208.021 | S9: 2655.119 | T9: 2929.347 | U9: 2912.028 | V9: 2780.247 | W9: 2875.574 | X9: 2959.641 | Y9: 2905.172 | Z9: 3516.64 | AA9: 3326.642 | AB9: 3602.586 | AC9: 3638.543 | AD9: 3957.832 | AE9: 4782.532 | AF9: 4725.393
A10: ATIVO CIRCULANTE | B10: Soma | C10: =C7+C8+C9 -> 4168.907 | D10: =D7+D8+D9 -> 5877.157 | E10: =E7+E8+E9 -> 5327.758 | F10: =F7+F8+F9 -> 6178.504 | G10: =G7+G8+G9 -> 6447.781 | H10: =H7+H8+H9 -> 8564.139 | I10: =I7+I8+I9 -> 9826.48 | J10: =J7+J8+J9 -> 9761.58 | ... AF10: =AF7+AF8+AF9 -> 13853.303
A11: Ativos de conteúdo (líquidos) | B11: nflx:ContentAssetsNet | C11: 20888.785 | D11: 21945.74 | E11: 23234.994 | F11: 24504.567 | G11: 25266.889 | H11: 25155.117 | I11: 25067.633 | J11: 25383.95 | K11: 26043.991 | L11: 27291.64 | M11: 28974.045 | N11: 30919.539 | O11: 31191.92 | P11: 32533.199 | Q11: 32777.34 | R11: 32736.713 | S11: 32349.184 | T11: 32520.774 | U11: 31749.861 | V11: 31658.056 | W11: 31662.1 | X11: 31927.355 | Y11: 32175.382 | Z11: 32452.462 | AA11: 32040.839 | AB11: 32089.394 | AC11: 32639.879 | AD11: 32778.392 | AE11: 33376.295 | AF11: 33837.573
A12: Imobilizado líquido | B12: PropertyPlantAndEquipmentNet | C12: 434.372 | D12: 452.399 | E12: 481.992 | F12: 565.221 | G12: 650.455 | H12: 751.941 | I12: 828.118 | J12: 960.183 | K12: 1015.419 | L12: 1107.437 | M12: 1220.114 | N12: 1323.453 | O12: 1383.763 | P12: 1361.92 | Q12: 1372.754 | R12: 1398.257 | S12: 1413.094 | T12: 1471.968 | U12: 1498.391 | V12: 1491.444 | W12: 1501.168 | X12: 1510.958 | Y12: 1568.212 | Z12: 1593.756 | AA12: 1644.346 | AB12: 1743.566 | AC12: 1837.889 | AD12: 2004.35 | AE12: 2147.829 | AF12: 2398.848
A13: Outros ativos não circulantes | B13: Ativo total − demais | C13: =C15-C10-C11-C12 -> 1726.568 | D13: =D15-D10-D11-D12 -> 1896.043 | E13: =E15-E10-E11-E12 -> 1896.967 | F13: =F15-F10-F11-F12 -> 2727.42 | G13: =G15-G10-G11-G12 -> 2694.785 | H13: =H15-H10-H11-H12 -> 2704.084 | I13: =I15-I10-I11-I12 -> 2900.312 | J13: =J15-J10-J11-J12 -> 3174.646 | ... AF13: =AF15-AF10-AF11-AF12 -> 8360.717
A14: ATIVO NÃO CIRCULANTE | B14: Soma | C14: =C11+C12+C13 -> 23049.725 | D14: =D11+D12+D13 -> 24294.182 | E14: =E11+E12+E13 -> 25613.953 | F14: =F11+F12+F13 -> 27797.208 | G14: =G11+G12+G13 -> 28612.129 | H14: =H11+H12+H13 -> 28611.142 | I14: =I11+I12+I13 -> 28796.063 | J14: =J11+J12+J13 -> 29518.779 | ... AF14: =AF11+AF12+AF13 -> 44597.138
A15: ATIVO TOTAL | B15: us-gaap:Assets | C15: 27218.632 | D15: 30171.339 | E15: 30941.711 | F15: 33975.712 | G15: 35059.91 | H15: 37175.281 | I15: 38622.543 | J15: 39280.359 | K15: 40123.014 | L15: 40970.969 | M15: 42739.857 | N15: 44584.663 | O15: 45330.904 | P15: 46350.935 | Q15: 47562.187 | R15: 48594.768 | S15: 49490.345 | T15: 50817.473 | U15: 49501.786 | V15: 48731.992 | W15: 48827.721 | X15: 49098.895 | Y15: 52281.844 | Z15: 53630.374 | AA15: 52087.644 | AB15: 53099.664 | AC15: 54934.835 | AD15: 55596.993 | AE15: 61015.914 | AF15: 58450.441
A17: Passivo e patrimônio líquido
A18: Passivos de conteúdo (curto prazo) | B18: nflx:ContentLiabilitiesCurrent | C18: 4863.351 | D18: 4848.201 | E18: 4860.542 | F18: 4413.561 | G18: 4761.585 | H18: 4664.733 | I18: 4599.654 | J18: 4429.536 | K18: 4297.957 | L18: 4197.874 | M18: 4110.962 | N18: 4292.967 | O18: 4066.289 | P18: 4174.966 | Q18: 4225.89 | R18: 4480.15 | S18: 4344.58 | T18: 4440.412 | U18: 4259.582 | V18: 4466.47 | W18: 4436.021 | X18: 4391.437 | Y18: 4489.971 | Z18: 4393.681 | AA18: 4128.905 | AB18: 4091.77 | AC18: 4102.64 | AD18: 4084.854 | AE18: 4052.278 | AF18: 3866.522
A19: Fornecedores | B19: AccountsPayableCurrent | C19: 439.496 | D19: 442.194 | E19: 444.129 | F19: 674.347 | G19: 545.488 | H19: 446.668 | I19: 541.298 | J19: 656.183 | K19: 532.942 | L19: 622.931 | M19: 643.059 | N19: 837.483 | O19: 617.202 | P19: 504.278 | Q19: 560.156 | R19: 671.513 | S19: 591.987 | T19: 615.374 | U19: 534.429 | V19: 747.412 | W19: 607.348 | X19: 598.557 | Y19: 641.953 | Z19: 899.909 | AA19: 614.489 | AB19: 632.718 | AC19: 793.233 | AD19: 900.612 | AE19: 894.681 | AF19: 814.551
A20: Despesas a pagar e provisões | B20: AccruedLiabilitiesCurrent | C20: 746.268 | D20: 750.812 | E20: 1037.723 | F20: 843.043 | G20: 1061.09 | H20: 986.595 | I20: 1259.124 | J20: 1102.196 | K20: 1291.812 | L20: 1125.591 | M20: 1413.12 | N20: 1449.351 | O20: 1817.117 | P20: 1596.035 | Q20: 1803.555 | R20: 1514.65 | S20: 1718.069 | T20: 1908.714 | U20: 1838.908 | V20: 1803.96 | W20: 1977.428 | X20: 1876.244 | Y20: 2241.758 | Z20: 2156.544 | AA20: 2359.518 | AB20: 2489.486 | AC20: 3111.311 | AD20: 3220.869 | AE20: 4441.986 | AF20: 3172.611
A21: Receita diferida (assinaturas pagas antecipadamente) | B21: ContractWithCustomerLiability | C21: 808.692 | D21: 892.777 | E21: 915.506 | F21: 925 | G21: 987 | H21: 1029 | I21: 1040 | J21: 1118 | K21: 1140 | L21: 1187 | M21: 1183 | N21: 1209 | O21: 1239 | P21: 1225 | Q21: 1176 | R21: 1265 | S21: 1262 | T21: 1312 | U21: 1306 | V21: 1443 | W21: 1469 | X21: 1474 | Y21: 1513 | Z21: 1521 | AA21: 1610 | AB21: 1728 | AC21: 1725 | AD21: 1776 | AE21: 1743 | AF21: 1797
A22: Dívida de curto prazo | B22: ShortTermBorrowings | C22: 0 | D22: 0 | E22: 0 | F22: 0 | G22: 499 | H22: 499 | I22: 500 | J22: 499.878 | K22: 699 | L22: 699 | M22: 699 | N22: 699.823 | O22: 0 | P22: 0 | Q22: 0 | R22: 0 | S22: 399 | T22: 399 | U22: 400 | V22: 399.844 | W22: 799 | X22: 1800 | Y22: 1820 | Z22: 1784.453 | AA22: 1006 | AB22: 0 | AC22: 0 | AD22: 998.865 | AE22: 999 | AF22: 2484
A23: Arredondamento entre balanço e notas (resíduo, < US$ 1 mi) | B23: PC informado − soma das linhas | C23: =C24-(C18+C19+C20+C21+C22) -> 0 | D23: =D24-(D18+D19+D20+D21+D22) -> 0 | E23: =E24-(E18+E19+E20+E21+E22) -> 0 | F23: =F24-(F18+F19+F20+F21+F22) -> -0.255 | G23: =G24-(G18+G19+G20+G21+G22) -> -0.438 | H23: =H24-(H18+H19+H20+H21+H22) -> 0.422 | I23: =I24-(I18+I19+I20+I21+I22) -> -0.281 | J23: =J24-(J18+J19+J20+J21+J22) -> -0.008 | ... AF23: =AF24-(AF18+AF19+AF20+AF21+AF22) -> 0.214
A24: PASSIVO CIRCULANTE | B24: LiabilitiesCurrent | C24: 6857.807 | D24: 6933.984 | E24: 7257.9 | F24: 6855.696 | G24: 7853.725 | H24: 7626.418 | I24: 7939.795 | J24: 7805.785 | K24: 7961.77 | L24: 7832.888 | M24: 8049.246 | N24: 8488.966 | O24: 7739.656 | P24: 7500.022 | Q24: 7765.924 | R24: 7930.974 | S24: 8316.07 | T24: 8675.805 | U24: 8338.718 | V24: 8860.655 | W24: 9289.217 | X24: 10139.999 | Y24: 10707.126 | Z24: 10755.4 | AA24: 9718.519 | AB24: 8942.335 | AC24: 9731.859 | AD24: 10980.93 | AE24: 12131.578 | AF24: 12134.898
A25: Passivos de conteúdo (longo prazo) | B25: nflx:ContentLiabilitiesNoncurrent | C25: 3560.364 | D25: 3564.44 | E25: 3419.552 | F25: 3334.323 | G25: 3206.051 | H25: 3208.164 | I25: 2926.574 | J25: 2618.084 | K25: 2465.626 | L25: 2265.286 | M25: 2301.026 | N25: 3094.213 | O25: 2945.221 | P25: 2989.961 | Q25: 2955.368 | R25: 3081.277 | S25: 2908.029 | T25: 2849.387 | U25: 2668.472 | V25: 2578.173 | W25: 2370.692 | X25: 2028.782 | Y25: 1918.089 | Z25: 1780.806 | AA25: 1696.662 | AB25: 1606.404 | AC25: 1591.973 | AD25: 1579.476 | AE25: 1626.498 | AF25: 1625.6
A26: Dívida de longo prazo | B26: LongTermDebtNoncurrent | C26: 10305.023 | D26: 12594 | E26: 12426 | F26: 14759 | G26: 14170.692 | H26: 15294.998 | I26: 15547.616 | J26: 15809.095 | K26: 14860.552 | L26: 14926.889 | M26: 14793.691 | N26: 14693.072 | O26: 14534.561 | P26: 14233.303 | Q26: 13888.117 | R26: 14353.076 | S26: 14037.965 | T26: 14070.151 | U26: 13900.754 | V26: 14143.417 | W26: 13217.038 | X26: 12180.024 | Y26: 14160.932 | Z26: 13798.351 | AA26: 14011.037 | AB26: 14453.206 | AC26: 14463.02 | AD26: 13463.971 | AE26: 13361.331 | AF26: 11825.548
A27: Outros passivos de longo prazo | B27: OtherLiabilitiesNoncurrent | C27: 792.38 | D27: 973.232 | E27: 977.008 | F27: 1444.276 | G27: 1420.148 | H27: 1710.948 | I27: 1875.235 | J27: 1982.155 | K27: 1950.986 | L27: 2082.035 | M27: 2281.277 | N27: 2459.164 | O27: 2567.427 | P27: 2551.675 | Q27: 2424.637 | R27: 2452.04 | S27: 2400.085 | T27: 2389.915 | U27: 2486.215 | V27: 2561.434 | W27: 2585.364 | X27: 2637.397 | Y27: 2774.961 | Z27: 2552.25 | AA27: 2633.353 | AB27: 3145.82 | AC27: 3193.948 | AD27: 2957.128 | AE27: 2770.108 | AF27: 2712.343
A28: Arredondamento entre balanço e notas (resíduo, < US$ 1 mi) | B28: PNC − soma das linhas | C28: =C29-(C25+C26+C27) -> 0 | D28: =D29-(D25+D26+D27) -> 0.135 | E28: =E29-(E25+E26+E27) -> -0.254 | F28: =F29-(F25+F26+F27) -> 0.26 | G28: =G29-(G25+G26+G27) -> 0 | H28: =H29-(H25+H26+H27) -> 0 | I28: =I29-(I25+I26+I27) -> 0 | J28: =J29-(J25+J26+J27) -> 0 | ... AF28: =AF29-(AF25+AF26+AF27) -> 0
A29: PASSIVO NÃO CIRCULANTE | B29: Passivo total − PC | C29: =C30-C24 -> 14657.767 | D29: =D30-D24 -> 17131.807 | E29: =E30-E24 -> 16822.306 | F29: =F30-F24 -> 19537.859 | G29: =G30-G24 -> 18796.891 | H29: =H30-H24 -> 20214.11 | I29: =I30-I24 -> 20349.425 | J29: =J30-J24 -> 20409.334 | ... AF29: =AF30-AF24 -> 16163.491
A30: PASSIVO TOTAL (exigível) | B30: us-gaap:Liabilities | C30: 21515.574 | D30: 24065.791 | E30: 24080.206 | F30: 26393.555 | G30: 26650.616 | H30: 27840.528 | I30: 28289.22 | J30: 28215.119 | K30: 27238.934 | L30: 27107.098 | M30: 27425.24 | N30: 28735.415 | O30: 27786.865 | P30: 27274.961 | Q30: 27034.046 | R30: 27817.367 | S30: 27662.149 | T30: 27985.258 | U30: 27394.159 | V30: 28143.679 | W30: 27462.311 | X30: 26986.202 | Y30: 29561.108 | Z30: 28886.807 | AA30: 28059.571 | AB30: 28147.765 | AC30: 28980.8 | AD30: 28981.505 | AE30: 29889.515 | AF30: 28298.389
A31: PATRIMÔNIO LÍQUIDO | B31: StockholdersEquity | C31: 5703.058 | D31: 6105.548 | E31: 6861.505 | F31: 7582.157 | G31: 8409.294 | H31: 9334.753 | I31: 10333.323 | J31: 11065.24 | K31: 12884.08 | L31: 13863.871 | M31: 15314.617 | N31: 15849.248 | O31: 17544.039 | P31: 19075.974 | Q31: 20528.141 | R31: 20777.401 | S31: 21828.196 | T31: 22832.215 | U31: 22107.627 | V31: 20588.313 | W31: 21365.41 | X31: 22112.693 | Y31: 22720.736 | Z31: 24743.567 | AA31: 24028.073 | AB31: 24951.899 | AC31: 25954.035 | AD31: 26615.488 | AE31: 31126.399 | AF31: 30152.052
A32: PASSIVO TOTAL + PL | B32: Soma | C32: =C30+C31 -> 27218.632 | D32: =D30+D31 -> 30171.339 | E32: =E30+E31 -> 30941.711 | F32: =F30+F31 -> 33975.712 | G32: =G30+G31 -> 35059.91 | H32: =H30+H31 -> 37175.281 | I32: =I30+I31 -> 38622.543 | J32: =J30+J31 -> 39280.359 | ... AF32: =AF30+AF31 -> 58450.441
A34: Conferências (devem dar zero)
A35: Ativo total − (Passivo + PL) | B35: Identidade contábil | C35: =C15-C32 -> 0 | D35: =D15-D32 -> 0 | E35: =E15-E32 -> 0 | F35: =F15-F32 -> 0 | G35: =G15-G32 -> 0 | H35: =H15-H32 -> 0 | I35: =I15-I32 -> 0 | J35: =J15-J32 -> 0 | ... AF35: =AF15-AF32 -> 0
A36: AC calculado − AC informado | B36: AssetsCurrent | C36: =C10-4168.907 -> 0 | D36: =D10-5877.157 -> 0 | E36: =E10-5327.758 -> 0 | F36: =F10-6178.504 -> 0 | G36: =G10-6447.781 -> 0 | H36: =H10-8564.139 -> 0 | I36: =I10-9826.48 -> 0 | J36: =J10-9761.58 -> 0 | K36: =K10-10107.508 -> 0 | L36: =L10-9604.276 -> 0 | M36: =M10-9415.787 -> 0 | N36: =N10-8069.825 -> 0 | O36: =O10-8098.015 -> 0 | P36: =P10-7840.778 -> 0 | Q36: =Q10-8816.903 -> 0 | R36: =R10-9266.473 -> 0 | S36: =S10-10482.623 -> 0 | T36: =T10-11506.336 -> 0 | U36: =U10-10779.474 -> 0 | V36: =V10-9918.133 -> 0 | W36: =W10-9921.313 -> 0 | X36: =X10-9615.553 -> 0 | Y36: =Y10-12129.099 -> 0 | Z36: =Z10-13100.379 -> 0 | AA36: =AA10-11697.632 -> 0 | AB36: =AB10-11993.106 -> 0 | AC36: =AC10-12962.935 -> 0 | AD36: =AD10-13020.191 -> 0 | AE36: =AE10-17070.982 -> 0 | AF36: =AF10-13853.303 -> 0
A37: Resíduo de arredondamento do PC (tolerância US$ 1 mi) | B37: Ver linha do resíduo | C37: =C23 -> 0 | D37: =D23 -> 0 | E37: =E23 -> 0 | F37: =F23 -> -0.255 | G37: =G23 -> -0.438 | H37: =H23 -> 0.422 | I37: =I23 -> -0.281 | J37: =J23 -> -0.008 | ... AF37: =AF23 -> 0.214
A38: Resíduo de arredondamento do PNC (tolerância US$ 1 mi) | B38: Ver linha do resíduo | C38: =C28 -> 0 | D38: =D28 -> 0.135 | E38: =E28 -> -0.254 | F38: =F28 -> 0.26 | G38: =G28 -> 0 | H38: =H28 -> 0 | I38: =I28 -> 0 | J38: =J28 -> 0 | ... AF38: =AF28 -> 0

Sheet DFC
A1: Netflix, Inc. — Fluxo de Caixa (trimestral)
A2: US$ milhões · Fonte: SEC EDGAR. 10-Q traz o acumulado do ano; trimestre = acumulado − acumulado anterior.
A4: Conta / indicador | B4: Fonte ou fórmula | C4: 2019T1 | D4: 2019T2 | E4: 2019T3 | F4: 2019T4 | G4: 2020T1 | H4: 2020T2 | I4: 2020T3 | J4: 2020T4 | K4: 2021T1 | L4: 2021T2 | M4: 2021T3 | N4: 2021T4 | O4: 2022T1 | P4: 2022T2 | Q4: 2022T3 | R4: 2022T4 | S4: 2023T1 | T4: 2023T2 | U4: 2023T3 | V4: 2023T4 | W4: 2024T1 | X4: 2024T2 | Y4: 2024T3 | Z4: 2024T4 | AA4: 2025T1 | AB4: 2025T2 | AC4: 2025T3 | AD4: 2025T4 | AE4: 2026T1 | AF4: 2026T2
A6: Fluxos de caixa
A7: Fluxo de caixa operacional (FCO) | B7: NetCashProvidedByOperating | C7: -379.799 | D7: -543.754 | E7: -501.794 | F7: -1461.975 | G7: 259.912 | H7: 1041.076 | I7: 1263.761 | J7: -137.672 | K7: 777.266 | L7: -63.761 | M7: 82.379 | N7: -403.274 | O7: 922.839 | P7: 102.75 | Q7: 556.81 | R7: 443.858 | S7: 2178.74 | T7: 1440.232 | U7: 1992.315 | V7: 1663.014 | W7: 2212.522 | X7: 1290.847 | Y7: 2321.101 | Z7: 1536.894 | AA7: 2789.199 | AB7: 2423.258 | AC7: 2825.174 | AD7: 2111.642 | AE7: 5290.205 | AF7: 1743.812
A8: (−) Compras de imobilizado (Capex) | B8: PaymentsToAcquirePP&E | C8: 60.381 | D8: 39.584 | E8: 45.333 | F8: 107.737 | G8: 98.015 | H8: 141.741 | I8: 109.811 | J8: 148.356 | K8: 81.001 | L8: 110.278 | M8: 167.327 | N8: 165.979 | O8: 121.158 | P8: 90.018 | Q8: 84.96 | R8: 111.593 | S8: 62.019 | T8: 100.972 | U8: 103.929 | V8: 81.632 | W8: 75.714 | X8: 78.287 | Y8: 126.863 | Z8: 158.674 | AA8: 128.277 | AB8: 155.889 | AC8: 164.719 | AD8: 239.335 | AE8: 196.13 | AF8: 218.644
A9: (=) Fluxo de caixa livre simplificado (FCO − Capex) | B9: FCO − Capex | C9: =C7-C8 -> -440.18 | D9: =D7-D8 -> -583.338 | E9: =E7-E8 -> -547.127 | F9: =F7-F8 -> -1569.712 | G9: =G7-G8 -> 161.897 | H9: =H7-H8 -> 899.335 | I9: =I7-I8 -> 1153.95 | J9: =J7-J8 -> -286.028 | ... AF9: =AF7-AF8 -> 1525.168
A10: Fluxo de caixa de investimento | B10: NetCashInvesting | C10: -80.103 | D10: -50.036 | E10: -49.354 | F10: -207.571 | G10: -98.303 | H10: -142.001 | I10: -118.651 | J10: -146.399 | K10: -85.616 | L10: -111.278 | M10: -188.631 | N10: -954.328 | O10: -245.679 | P10: -158.894 | Q10: -84.96 | R10: -1586.859 | S10: -263.653 | T10: 97.737 | U10: 296.071 | V10: 411.596 | W10: -75.714 | X10: -78.287 | Y10: -1869.109 | Z10: -158.674 | AA10: 485.662 | AB10: 768.684 | AC10: 43.871 | AD10: -256.529 | AE10: -781.874 | AF10: -218.644
A11: Fluxo de caixa de financiamento | B11: NetCashFinancing | C11: 22.972 | D11: 2246.9 | E11: 11.989 | F11: 2223.801 | G11: 43.694 | H11: 1090.965 | I11: 68.665 | J11: 33.987 | K11: -451.929 | L11: -480.273 | M11: -81.555 | N11: -136.019 | O11: -686.322 | P11: 11.25 | Q11: 4.113 | R11: 6.705 | S11: -374.073 | T11: -649.349 | U11: -2475.108 | V11: -2452.273 | W11: -2132.944 | X11: -1489.381 | Y11: 226.596 | Z11: -678.698 | AA11: -4028.316 | AB11: -2502.868 | AC11: -1737.029 | AD11: -2077.41 | AE11: -1230.814 | AF11: -4669.627
A12: Recompra de ações (saída de caixa) | B12: PaymentsForRepurchaseOfCommonStock | C12: 0 | D12: 0 | E12: 0 | F12: 0 | G12: 0 | H12: 0 | I12: 0 | J12: 0 | K12: 0 | L12: 500.022 | M12: 100 | N12: 0 | O12: 0 | P12: 0 | Q12: 0 | R12: 0 | S12: 400.101 | T12: 645.146 | U12: 2500.1 | V12: 2500 | W12: 2000 | X12: 1599.998 | Y12: 1700 | Z12: 963.748 | AA12: 3536.396 | AB12: 1654.327 | AC12: 1856.885 | AD12: 2079.559 | AE12: 1270.588 | AF12: 4714.403
A14: Conteúdo: competência x caixa (a chave para entender o caixa da Netflix)
A15: Pagamentos de conteúdo (caixa) | B15: nflx:AdditionsToStreamingContentAssets | C15: 2997.746 | D15: 3325.103 | E15: 3648.292 | F15: 3945.542 | G15: 3294.275 | H15: 2510.782 | I15: 2653.886 | J15: 3320.341 | K15: 3284.576 | L15: 4096.75 | M15: 4666.237 | N15: 5654.639 | O15: 3584.164 | P15: 4687.011 | Q15: 4582.671 | R15: 3985.192 | S15: 2458.666 | T15: 3683.007 | U15: 2883.839 | V15: 3529.191 | W15: 3728.967 | X15: 4048.852 | Y15: 4016.396 | Z15: 4429.402 | AA15: 3549.657 | AB15: 3835.813 | AC15: 4653.935 | AD15: 5057.212 | AE15: 4846.917 | AF15: 4927.523
A16: Amortização de conteúdo (DRE) | B16: Igual à DRE | C16: =DRE!C28 -> 2124.686 | D16: =DRE!D28 -> 2231.915 | E16: =DRE!E28 -> 2279.977 | F16: =DRE!F28 -> 2579.669 | G16: =DRE!G28 -> 2483.385 | H16: =DRE!H28 -> 2607.159 | I16: =DRE!I28 -> 2733.743 | J16: =DRE!J28 -> 2982.625 | ... AF16: =DRE!AF28 -> 4311.309
A17: Razão pagamento / amortização | B17: > 1 = investe mais do que amortiza | C17: =IFERROR(C15/C16,"") -> 1.4109125 | D17: =IFERROR(D15/D16,"") -> 1.4897982 | E17: =IFERROR(E15/E16,"") -> 1.6001442 | F17: =IFERROR(F15/F16,"") -> 1.5294761 | G17: =IFERROR(G15/G16,"") -> 1.3265261 | H17: =IFERROR(H15/H16,"") -> 0.96303371 | I17: =IFERROR(I15/I16,"") -> 0.9707884 | J17: =IFERROR(J15/J16,"") -> 1.1132278 | ... AF17: =IFERROR(AF15/AF16,"") -> 1.1429297
A18: Remuneração em ações (não-caixa) | B18: ShareBasedCompensation | C18: 101.2 | D18: 103.848 | E18: 100.262 | F18: 100.066 | G18: 97.019 | H18: 104.21 | I18: 106.357 | J18: 107.594 | K18: 107.23 | L18: 101.583 | M18: 95.078 | N18: 99.329 | O18: 119.209 | P18: 150.392 | Q18: 152.062 | R18: 153.789 | S18: 99.099 | T18: 78.03 | U18: 79.72 | V18: 82.519 | W18: 76.345 | X18: 68.766 | Y18: 65.65 | Z18: 61.827 | AA18: 71.977 | AB18: 80.862 | AC18: 80.986 | AD18: 134.624 | AE18: 140.405 | AF18: 131.312
A20: A Netflix define FCL como FCO − Capex − variação de outros ativos; a versão simplificada daqui difere em poucos milhões.

Sheet AV
A1: Análise Vertical (AV)
A2: DRE: % da Receita líquida · BP: % do Ativo total — fórmula da disciplina: conta / base
A4: Conta / indicador | B4: Fonte ou fórmula | C4: 2019T1 | D4: 2019T2 | E4: 2019T3 | F4: 2019T4 | G4: 2020T1 | H4: 2020T2 | I4: 2020T3 | J4: 2020T4 | K4: 2021T1 | L4: 2021T2 | M4: 2021T3 | N4: 2021T4 | O4: 2022T1 | P4: 2022T2 | Q4: 2022T3 | R4: 2022T4 | S4: 2023T1 | T4: 2023T2 | U4: 2023T3 | V4: 2023T4 | W4: 2024T1 | X4: 2024T2 | Y4: 2024T3 | Z4: 2024T4 | AA4: 2025T1 | AB4: 2025T2 | AC4: 2025T3 | AD4: 2025T4 | AE4: 2026T1 | AF4: 2026T2
A6: DRE — % da receita líquida
A7: Receita líquida | C7: =IFERROR(DRE!C7/DRE!C7,"") -> 1 | D7: =IFERROR(DRE!D7/DRE!D7,"") -> 1 | E7: =IFERROR(DRE!E7/DRE!E7,"") -> 1 | F7: =IFERROR(DRE!F7/DRE!F7,"") -> 1 | G7: =IFERROR(DRE!G7/DRE!G7,"") -> 1 | H7: =IFERROR(DRE!H7/DRE!H7,"") -> 1 | I7: =IFERROR(DRE!I7/DRE!I7,"") -> 1 | J7: =IFERROR(DRE!J7/DRE!J7,"") -> 1 | ... AF7: =IFERROR(DRE!AF7/DRE!AF7,"") -> 1
A8: Custo dos serviços | C8: =IFERROR(DRE!C8/DRE!C7,"") -> 0.63495224 | D8: =IFERROR(DRE!D8/DRE!D7,"") -> 0.61051923 | E8: =IFERROR(DRE!E8/DRE!E7,"") -> 0.59065302 | F8: =IFERROR(DRE!F8/DRE!F7,"") -> 0.63393961 | G8: =IFERROR(DRE!G8/DRE!G7,"") -> 0.62411475 | H8: =IFERROR(DRE!H8/DRE!H7,"") -> 0.59263785 | I8: =IFERROR(DRE!I8/DRE!I7,"") -> 0.60098961 | J8: =IFERROR(DRE!J8/DRE!J7,"") -> 0.62686378 | ... AF8: =IFERROR(DRE!AF8/DRE!AF7,"") -> 0.48065245
A9: Lucro bruto | C9: =IFERROR(DRE!C9/DRE!C7,"") -> 0.36504776 | D9: =IFERROR(DRE!D9/DRE!D7,"") -> 0.38948077 | E9: =IFERROR(DRE!E9/DRE!E7,"") -> 0.40934698 | F9: =IFERROR(DRE!F9/DRE!F7,"") -> 0.36606039 | G9: =IFERROR(DRE!G9/DRE!G7,"") -> 0.37588525 | H9: =IFERROR(DRE!H9/DRE!H7,"") -> 0.40736215 | I9: =IFERROR(DRE!I9/DRE!I7,"") -> 0.39901039 | J9: =IFERROR(DRE!J9/DRE!J7,"") -> 0.37313622 | ... AF9: =IFERROR(DRE!AF9/DRE!AF7,"") -> 0.51934755
A10: Marketing | C10: =IFERROR(DRE!C10/DRE!C7,"") -> 0.13638113 | D10: =IFERROR(DRE!D10/DRE!D7,"") -> 0.12251387 | E10: =IFERROR(DRE!E10/DRE!E7,"") -> 0.10558761 | F10: =IFERROR(DRE!F10/DRE!F7,"") -> 0.16075859 | G10: =IFERROR(DRE!G10/DRE!G7,"") -> 0.087353847 | H10: =IFERROR(DRE!H10/DRE!H7,"") -> 0.070648958 | I10: =IFERROR(DRE!I10/DRE!I7,"") -> 0.081980541 | J10: =IFERROR(DRE!J10/DRE!J7,"") -> 0.11476735 | ... AF10: =IFERROR(DRE!AF10/DRE!AF7,"") -> 0.065592521
A11: Tecnologia | C11: =IFERROR(DRE!C11/DRE!C7,"") -> 0.082451816 | D11: =IFERROR(DRE!D11/DRE!D7,"") -> 0.077843585 | E11: =IFERROR(DRE!E11/DRE!E7,"") -> 0.072408556 | F11: =IFERROR(DRE!F11/DRE!F7,"") -> 0.074875344 | G11: =IFERROR(DRE!G11/DRE!G7,"") -> 0.078682613 | H11: =IFERROR(DRE!H11/DRE!H7,"") -> 0.070758745 | I11: =IFERROR(DRE!I11/DRE!I7,"") -> 0.070513921 | J11: =IFERROR(DRE!J11/DRE!J7,"") -> 0.073284709 | ... AF11: =IFERROR(DRE!AF11/DRE!AF7,"") -> 0.080229297
A12: Gerais e administrativas | C12: =IFERROR(DRE!C12/DRE!C7,"") -> 0.044669842 | D12: =IFERROR(DRE!D12/DRE!D7,"") -> 0.045633091 | E12: =IFERROR(DRE!E12/DRE!E7,"") -> 0.04445724 | F12: =IFERROR(DRE!F12/DRE!F7,"") -> 0.046564074 | G12: =IFERROR(DRE!G12/DRE!G7,"") -> 0.043706745 | H12: =IFERROR(DRE!H12/DRE!H7,"") -> 0.045091591 | I12: =IFERROR(DRE!I12/DRE!I7,"") -> 0.042206234 | J12: =IFERROR(DRE!J12/DRE!J7,"") -> 0.041469096 | ... AF12: =IFERROR(DRE!AF12/DRE!AF7,"") -> 0.039717553
A13: EBIT | C13: =IFERROR(DRE!C14/DRE!C7,"") -> 0.10154497 | D13: =IFERROR(DRE!D14/DRE!D7,"") -> 0.14349022 | E13: =IFERROR(DRE!E14/DRE!E7,"") -> 0.18689357 | F13: =IFERROR(DRE!F14/DRE!F7,"") -> 0.083862375 | G13: =IFERROR(DRE!G14/DRE!G7,"") -> 0.16614205 | H13: =IFERROR(DRE!H14/DRE!H7,"") -> 0.22086286 | I13: =IFERROR(DRE!I14/DRE!I7,"") -> 0.20430969 | J13: =IFERROR(DRE!J14/DRE!J7,"") -> 0.14361507 | ... AF13: =IFERROR(DRE!AF14/DRE!AF7,"") -> 0.33380818
A14: Despesa de juros | C14: =IFERROR(DRE!C15/DRE!C7,"") -> 0.029977713 | D14: =IFERROR(DRE!D15/DRE!D7,"") -> 0.030881458 | E14: =IFERROR(DRE!E15/DRE!E7,"") -> 0.030631632 | F14: =IFERROR(DRE!F15/DRE!F7,"") -> 0.032520008 | G14: =IFERROR(DRE!G15/DRE!G7,"") -> 0.031916238 | H14: =IFERROR(DRE!H15/DRE!H7,"") -> 0.030764834 | I14: =IFERROR(DRE!I15/DRE!I7,"") -> 0.030623076 | J14: =IFERROR(DRE!J15/DRE!J7,"") -> 0.029676834 | ... AF14: =IFERROR(DRE!AF15/DRE!AF7,"") -> 0.013987728
A15: Outras receitas/despesas financeiras | C15: =IFERROR(DRE!C16/DRE!C7,"") -> 0.016833474 | D15: =IFERROR(DRE!D16/DRE!D7,"") -> -0.010861008 | E15: =IFERROR(DRE!E16/DRE!E7,"") -> 0.036748807 | F15: =IFERROR(DRE!F16/DRE!F7,"") -> -0.024029188 | G15: =IFERROR(DRE!G16/DRE!G7,"") -> 0.0037618173 | H15: =IFERROR(DRE!H16/DRE!H7,"") -> -0.021660508 | I15: =IFERROR(DRE!I16/DRE!I7,"") -> -0.039828847 | J15: =IFERROR(DRE!J16/DRE!J7,"") -> -0.037721603 | ... AF15: =IFERROR(DRE!AF16/DRE!AF7,"") -> 0.0041131572
A16: LAIR | C16: =IFERROR(DRE!C17/DRE!C7,"") -> 0.088400732 | D16: =IFERROR(DRE!D17/DRE!D7,"") -> 0.10174775 | E16: =IFERROR(DRE!E17/DRE!E7,"") -> 0.19301074 | F16: =IFERROR(DRE!F17/DRE!F7,"") -> 0.027313178 | G16: =IFERROR(DRE!G17/DRE!G7,"") -> 0.13798763 | H16: =IFERROR(DRE!H17/DRE!H7,"") -> 0.16843751 | I16: =IFERROR(DRE!I17/DRE!I7,"") -> 0.13385777 | J16: =IFERROR(DRE!J17/DRE!J7,"") -> 0.076216633 | ... AF16: =IFERROR(DRE!AF17/DRE!AF7,"") -> 0.32393361
A17: Imposto de renda | C17: =IFERROR(DRE!C18/DRE!C7,"") -> 0.012299734 | D17: =IFERROR(DRE!D18/DRE!D7,"") -> 0.04677241 | E17: =IFERROR(DRE!E18/DRE!E7,"") -> 0.066174506 | F17: =IFERROR(DRE!F18/DRE!F7,"") -> -0.080044313 | G17: =IFERROR(DRE!G18/DRE!G7,"") -> 0.01504987 | H17: =IFERROR(DRE!H18/DRE!H7,"") -> 0.051299826 | I17: =IFERROR(DRE!I18/DRE!I7,"") -> 0.011107525 | J17: =IFERROR(DRE!J18/DRE!J7,"") -> -0.0053787812 | ... AF17: =IFERROR(DRE!AF18/DRE!AF7,"") -> 0.053119052
A18: Lucro líquido | C18: =IFERROR(DRE!C19/DRE!C7,"") -> 0.076100997 | D18: =IFERROR(DRE!D19/DRE!D7,"") -> 0.054975345 | E18: =IFERROR(DRE!E19/DRE!E7,"") -> 0.12683623 | F18: =IFERROR(DRE!F19/DRE!F7,"") -> 0.10735749 | G18: =IFERROR(DRE!G19/DRE!G7,"") -> 0.12293776 | H18: =IFERROR(DRE!H19/DRE!H7,"") -> 0.11713769 | I18: =IFERROR(DRE!I19/DRE!I7,"") -> 0.12275024 | J18: =IFERROR(DRE!J19/DRE!J7,"") -> 0.081595415 | ... AF18: =IFERROR(DRE!AF19/DRE!AF7,"") -> 0.27081455
A19: Amortização de conteúdo | C19: =IFERROR(DRE!C28/DRE!C7,"") -> 0.46996013 | D19: =IFERROR(DRE!D28/DRE!D7,"") -> 0.45335414 | E19: =IFERROR(DRE!E28/DRE!E7,"") -> 0.4347032 | F19: =IFERROR(DRE!F28/DRE!F7,"") -> 0.47182444 | G19: =IFERROR(DRE!G28/DRE!G7,"") -> 0.43056832 | H19: =IFERROR(DRE!H28/DRE!H7,"") -> 0.42404647 | I19: =IFERROR(DRE!I28/DRE!I7,"") -> 0.42478204 | J19: =IFERROR(DRE!J28/DRE!J7,"") -> 0.44889022 | ... AF19: =IFERROR(DRE!AF28/DRE!AF7,"") -> 0.34325878
A20: EBITDA | C20: =IFERROR(DRE!C30/DRE!C7,"") -> 0.10675644 | D20: =IFERROR(DRE!D30/DRE!D7,"") -> 0.14866905 | E20: =IFERROR(DRE!E30/DRE!E7,"") -> 0.19198498 | F20: =IFERROR(DRE!F30/DRE!F7,"") -> 0.088950319 | G20: =IFERROR(DRE!G30/DRE!G7,"") -> 0.17108632 | H20: =IFERROR(DRE!H30/DRE!H7,"") -> 0.22519919 | I20: =IFERROR(DRE!I30/DRE!I7,"") -> 0.20875199 | J20: =IFERROR(DRE!J30/DRE!J7,"") -> 0.14842255 | ... AF20: =IFERROR(DRE!AF30/DRE!AF7,"") -> 0.3418122
A22: Balanço — % do ativo total
A23: Caixa | C23: =IFERROR(BP!C7/BP!C15,"") -> 0.12302444 | D23: =IFERROR(BP!D7/BP!D15,"") -> 0.16586095 | E23: =IFERROR(BP!E7/BP!E15,"") -> 0.14333461 | F23: =IFERROR(BP!F7/BP!F15,"") -> 0.1477066 | G23: =IFERROR(BP!G7/BP!G15,"") -> 0.14694516 | H23: =IFERROR(BP!H7/BP!H15,"") -> 0.19241947 | I23: =IFERROR(BP!I7/BP!I15,"") -> 0.21729255 | J23: =IFERROR(BP!J7/BP!J15,"") -> 0.20889702 | ... AF23: =IFERROR(BP!AF7/BP!AF15,"") -> 0.15567431
A24: Aplicações CP | C24: =IFERROR(BP!C8/BP!C15,"") -> 0 | D24: =IFERROR(BP!D8/BP!D15,"") -> 0 | E24: =IFERROR(BP!E8/BP!E15,"") -> 0 | F24: =IFERROR(BP!F8/BP!F15,"") -> 0 | G24: =IFERROR(BP!G8/BP!G15,"") -> 0 | H24: =IFERROR(BP!H8/BP!H15,"") -> 0 | I24: =IFERROR(BP!I8/BP!I15,"") -> 0 | J24: =IFERROR(BP!J8/BP!J15,"") -> 0 | ... AF24: =IFERROR(BP!AF8/BP!AF15,"") -> 0.00049063787
A25: Outros AC | C25: =IFERROR(BP!C9/BP!C15,"") -> 0.030139281 | D25: =IFERROR(BP!D9/BP!D15,"") -> 0.028931762 | E25: =IFERROR(BP!E9/BP!E15,"") -> 0.028852315 | F25: =IFERROR(BP!F9/BP!F15,"") -> 0.034144009 | G25: =IFERROR(BP!G9/BP!G15,"") -> 0.03696236 | H25: =IFERROR(BP!H9/BP!H15,"") -> 0.037952396 | I25: =IFERROR(BP!I9/BP!I15,"") -> 0.03713088 | J25: =IFERROR(BP!J9/BP!J15,"") -> 0.039613436 | ... AF25: =IFERROR(BP!AF9/BP!AF15,"") -> 0.080844437
A26: Ativo circulante | C26: =IFERROR(BP!C10/BP!C15,"") -> 0.15316372 | D26: =IFERROR(BP!D10/BP!D15,"") -> 0.19479271 | E26: =IFERROR(BP!E10/BP!E15,"") -> 0.17218692 | F26: =IFERROR(BP!F10/BP!F15,"") -> 0.18185061 | G26: =IFERROR(BP!G10/BP!G15,"") -> 0.18390752 | H26: =IFERROR(BP!H10/BP!H15,"") -> 0.23037187 | I26: =IFERROR(BP!I10/BP!I15,"") -> 0.25442343 | J26: =IFERROR(BP!J10/BP!J15,"") -> 0.24851046 | ... AF26: =IFERROR(BP!AF10/BP!AF15,"") -> 0.23700938
A27: Ativos de conteúdo | C27: =IFERROR(BP!C11/BP!C15,"") -> 0.76744434 | D27: =IFERROR(BP!D11/BP!D15,"") -> 0.72737044 | E27: =IFERROR(BP!E11/BP!E15,"") -> 0.7509279 | F27: =IFERROR(BP!F11/BP!F15,"") -> 0.72123778 | G27: =IFERROR(BP!G11/BP!G15,"") -> 0.72067752 | H27: =IFERROR(BP!H11/BP!H15,"") -> 0.67666246 | I27: =IFERROR(BP!I11/BP!I15,"") -> 0.64904149 | J27: =IFERROR(BP!J11/BP!J15,"") -> 0.646225 | ... AF27: =IFERROR(BP!AF11/BP!AF15,"") -> 0.57891048
A28: Imobilizado | C28: =IFERROR(BP!C12/BP!C15,"") -> 0.015958627 | D28: =IFERROR(BP!D12/BP!D15,"") -> 0.01499433 | E28: =IFERROR(BP!E12/BP!E15,"") -> 0.015577419 | F28: =IFERROR(BP!F12/BP!F15,"") -> 0.016636031 | G28: =IFERROR(BP!G12/BP!G15,"") -> 0.018552672 | H28: =IFERROR(BP!H12/BP!H15,"") -> 0.020226908 | I28: =IFERROR(BP!I12/BP!I15,"") -> 0.021441312 | J28: =IFERROR(BP!J12/BP!J15,"") -> 0.024444354 | ... AF28: =IFERROR(BP!AF12/BP!AF15,"") -> 0.041040717
A29: Outros ANC | C29: =IFERROR(BP!C13/BP!C15,"") -> 0.063433313 | D29: =IFERROR(BP!D13/BP!D15,"") -> 0.062842521 | E29: =IFERROR(BP!E13/BP!E15,"") -> 0.06130776 | F29: =IFERROR(BP!F13/BP!F15,"") -> 0.08027558 | G29: =IFERROR(BP!G13/BP!G15,"") -> 0.076862291 | H29: =IFERROR(BP!H13/BP!H15,"") -> 0.072738764 | I29: =IFERROR(BP!I13/BP!I15,"") -> 0.075093761 | J29: =IFERROR(BP!J13/BP!J15,"") -> 0.080820188 | ... AF29: =IFERROR(BP!AF13/BP!AF15,"") -> 0.14303942
A30: Ativo total | C30: =IFERROR(BP!C15/BP!C15,"") -> 1 | D30: =IFERROR(BP!D15/BP!D15,"") -> 1 | E30: =IFERROR(BP!E15/BP!E15,"") -> 1 | F30: =IFERROR(BP!F15/BP!F15,"") -> 1 | G30: =IFERROR(BP!G15/BP!G15,"") -> 1 | H30: =IFERROR(BP!H15/BP!H15,"") -> 1 | I30: =IFERROR(BP!I15/BP!I15,"") -> 1 | J30: =IFERROR(BP!J15/BP!J15,"") -> 1 | ... AF30: =IFERROR(BP!AF15/BP!AF15,"") -> 1
A31: Passivo de conteúdo CP | C31: =IFERROR(BP!C18/BP!C15,"") -> 0.17867728 | D31: =IFERROR(BP!D18/BP!D15,"") -> 0.16068896 | E31: =IFERROR(BP!E18/BP!E15,"") -> 0.15708705 | F31: =IFERROR(BP!F18/BP!F15,"") -> 0.12990341 | G31: =IFERROR(BP!G18/BP!G15,"") -> 0.13581281 | H31: =IFERROR(BP!H18/BP!H15,"") -> 0.12547943 | I31: =IFERROR(BP!I18/BP!I15,"") -> 0.11909247 | J31: =IFERROR(BP!J18/BP!J15,"") -> 0.1127672 | ... AF31: =IFERROR(BP!AF18/BP!AF15,"") -> 0.066150433
A32: Fornecedores | C32: =IFERROR(BP!C19/BP!C15,"") -> 0.016146881 | D32: =IFERROR(BP!D19/BP!D15,"") -> 0.014656095 | E32: =IFERROR(BP!E19/BP!E15,"") -> 0.014353731 | F32: =IFERROR(BP!F19/BP!F15,"") -> 0.019847914 | G32: =IFERROR(BP!G19/BP!G15,"") -> 0.015558739 | H32: =IFERROR(BP!H19/BP!H15,"") -> 0.012015188 | I32: =IFERROR(BP!I19/BP!I15,"") -> 0.014015079 | J32: =IFERROR(BP!J19/BP!J15,"") -> 0.016705117 | ... AF32: =IFERROR(BP!AF19/BP!AF15,"") -> 0.013935755
A33: Provisões | C33: =IFERROR(BP!C20/BP!C15,"") -> 0.027417543 | D33: =IFERROR(BP!D20/BP!D15,"") -> 0.024884941 | E33: =IFERROR(BP!E20/BP!E15,"") -> 0.033537997 | F33: =IFERROR(BP!F20/BP!F15,"") -> 0.024813108 | G33: =IFERROR(BP!G20/BP!G15,"") -> 0.030265052 | H33: =IFERROR(BP!H20/BP!H15,"") -> 0.026539006 | I33: =IFERROR(BP!I20/BP!I15,"") -> 0.032600753 | J33: =IFERROR(BP!J20/BP!J15,"") -> 0.028059723 | ... AF33: =IFERROR(BP!AF20/BP!AF15,"") -> 0.054278649
A34: Receita diferida | C34: =IFERROR(BP!C21/BP!C15,"") -> 0.029710972 | D34: =IFERROR(BP!D21/BP!D15,"") -> 0.029590235 | E34: =IFERROR(BP!E21/BP!E15,"") -> 0.029588086 | F34: =IFERROR(BP!F21/BP!F15,"") -> 0.027225331 | G34: =IFERROR(BP!G21/BP!G15,"") -> 0.028151812 | H34: =IFERROR(BP!H21/BP!H15,"") -> 0.027679683 | I34: =IFERROR(BP!I21/BP!I15,"") -> 0.026927279 | J34: =IFERROR(BP!J21/BP!J15,"") -> 0.028462062 | ... AF34: =IFERROR(BP!AF21/BP!AF15,"") -> 0.030743994
A35: Dívida CP | C35: =IFERROR(BP!C22/BP!C15,"") -> 0 | D35: =IFERROR(BP!D22/BP!D15,"") -> 0 | E35: =IFERROR(BP!E22/BP!E15,"") -> 0 | F35: =IFERROR(BP!F22/BP!F15,"") -> 0 | G35: =IFERROR(BP!G22/BP!G15,"") -> 0.01423278 | H35: =IFERROR(BP!H22/BP!H15,"") -> 0.013422898 | I35: =IFERROR(BP!I22/BP!I15,"") -> 0.012945807 | J35: =IFERROR(BP!J22/BP!J15,"") -> 0.012725902 | ... AF35: =IFERROR(BP!AF22/BP!AF15,"") -> 0.042497541
A36: Passivo circulante | C36: =IFERROR(BP!C24/BP!C15,"") -> 0.25195267 | D36: =IFERROR(BP!D24/BP!D15,"") -> 0.22982023 | E36: =IFERROR(BP!E24/BP!E15,"") -> 0.23456686 | F36: =IFERROR(BP!F24/BP!F15,"") -> 0.20178226 | G36: =IFERROR(BP!G24/BP!G15,"") -> 0.2240087 | H36: =IFERROR(BP!H24/BP!H15,"") -> 0.20514755 | I36: =IFERROR(BP!I24/BP!I15,"") -> 0.20557411 | J36: =IFERROR(BP!J24/BP!J15,"") -> 0.1987198 | ... AF36: =IFERROR(BP!AF24/BP!AF15,"") -> 0.20761003
A37: Passivo de conteúdo LP | C37: =IFERROR(BP!C25/BP!C15,"") -> 0.13080613 | D37: =IFERROR(BP!D25/BP!D15,"") -> 0.11813993 | E37: =IFERROR(BP!E25/BP!E15,"") -> 0.11051593 | F37: =IFERROR(BP!F25/BP!F15,"") -> 0.098138429 | G37: =IFERROR(BP!G25/BP!G15,"") -> 0.09144493 | H37: =IFERROR(BP!H25/BP!H15,"") -> 0.086298312 | I37: =IFERROR(BP!I25/BP!I15,"") -> 0.075773726 | J37: =IFERROR(BP!J25/BP!J15,"") -> 0.066651224 | ... AF37: =IFERROR(BP!AF25/BP!AF15,"") -> 0.027811595
A38: Dívida LP | C38: =IFERROR(BP!C26/BP!C15,"") -> 0.3786018 | D38: =IFERROR(BP!D26/BP!D15,"") -> 0.41741601 | E38: =IFERROR(BP!E26/BP!E15,"") -> 0.40159382 | F38: =IFERROR(BP!F26/BP!F15,"") -> 0.43439855 | G38: =IFERROR(BP!G26/BP!G15,"") -> 0.40418506 | H38: =IFERROR(BP!H26/BP!H15,"") -> 0.41142925 | I38: =IFERROR(BP!I26/BP!I15,"") -> 0.40255288 | J38: =IFERROR(BP!J26/BP!J15,"") -> 0.40246819 | ... AF38: =IFERROR(BP!AF26/BP!AF15,"") -> 0.20231752
A39: Outros PLP | C39: =IFERROR(BP!C27/BP!C15,"") -> 0.029111676 | D39: =IFERROR(BP!D27/BP!D15,"") -> 0.032256838 | E39: =IFERROR(BP!E27/BP!E15,"") -> 0.031575759 | F39: =IFERROR(BP!F27/BP!F15,"") -> 0.042509072 | G39: =IFERROR(BP!G27/BP!G15,"") -> 0.040506322 | H39: =IFERROR(BP!H27/BP!H15,"") -> 0.046023808 | I39: =IFERROR(BP!I27/BP!I15,"") -> 0.048552862 | J39: =IFERROR(BP!J27/BP!J15,"") -> 0.050461733 | ... AF39: =IFERROR(BP!AF27/BP!AF15,"") -> 0.046404149
A40: Passivo não circulante | C40: =IFERROR(BP!C29/BP!C15,"") -> 0.53851961 | D40: =IFERROR(BP!D29/BP!D15,"") -> 0.56781726 | E40: =IFERROR(BP!E29/BP!E15,"") -> 0.5436773 | F40: =IFERROR(BP!F29/BP!F15,"") -> 0.5750537 | G40: =IFERROR(BP!G29/BP!G15,"") -> 0.53613632 | H40: =IFERROR(BP!H29/BP!H15,"") -> 0.54375137 | I40: =IFERROR(BP!I29/BP!I15,"") -> 0.52687947 | J40: =IFERROR(BP!J29/BP!J15,"") -> 0.51958115 | ... AF40: =IFERROR(BP!AF29/BP!AF15,"") -> 0.27653326
A41: Patrimônio líquido | C41: =IFERROR(BP!C31/BP!C15,"") -> 0.20952772 | D41: =IFERROR(BP!D31/BP!D15,"") -> 0.20236251 | E41: =IFERROR(BP!E31/BP!E15,"") -> 0.22175584 | F41: =IFERROR(BP!F31/BP!F15,"") -> 0.22316404 | G41: =IFERROR(BP!G31/BP!G15,"") -> 0.23985498 | H41: =IFERROR(BP!H31/BP!H15,"") -> 0.25110107 | I41: =IFERROR(BP!I31/BP!I15,"") -> 0.26754642 | J41: =IFERROR(BP!J31/BP!J15,"") -> 0.28169905 | ... AF41: =IFERROR(BP!AF31/BP!AF15,"") -> 0.51585671
A42: Passivo + PL | C42: =IFERROR(BP!C32/BP!C15,"") -> 1 | D42: =IFERROR(BP!D32/BP!D15,"") -> 1 | E42: =IFERROR(BP!E32/BP!E15,"") -> 1 | F42: =IFERROR(BP!F32/BP!F15,"") -> 1 | G42: =IFERROR(BP!G32/BP!G15,"") -> 1 | H42: =IFERROR(BP!H32/BP!H15,"") -> 1 | I42: =IFERROR(BP!I32/BP!I15,"") -> 1 | J42: =IFERROR(BP!J32/BP!J15,"") -> 1 | ... AF42: =IFERROR(BP!AF32/BP!AF15,"") -> 1

Sheet AH
A1: Análise Horizontal (AH) — trimestral
A2: Fórmula da disciplina: (Atual − Anterior) / ABS(Anterior). Cores: azul = alta, vermelho = queda; borda laranja = variação brusca (|AH| ≥ 50%).
A4: Conta / indicador | B4: Fonte ou fórmula | C4: 2019T1 | D4: 2019T2 | E4: 2019T3 | F4: 2019T4 | G4: 2020T1 | H4: 2020T2 | I4: 2020T3 | J4: 2020T4 | K4: 2021T1 | L4: 2021T2 | M4: 2021T3 | N4: 2021T4 | O4: 2022T1 | P4: 2022T2 | Q4: 2022T3 | R4: 2022T4 | S4: 2023T1 | T4: 2023T2 | U4: 2023T3 | V4: 2023T4 | W4: 2024T1 | X4: 2024T2 | Y4: 2024T3 | Z4: 2024T4 | AA4: 2025T1 | AB4: 2025T2 | AC4: 2025T3 | AD4: 2025T4 | AE4: 2026T1 | AF4: 2026T2
A6: AH homóloga — trimestre contra o mesmo trimestre do ano anterior (t vs t−4): elimina a sazonalidade
A7: Receita líquida | B7: DRE | C7: n.d. | D7: n.d. | E7: n.d. | F7: n.d. | G7: =IFERROR((DRE!G7-DRE!C7)/ABS(DRE!C7),"") -> 0.27575784 | H7: =IFERROR((DRE!H7-DRE!D7)/ABS(DRE!D7),"") -> 0.24886068 | I7: =IFERROR((DRE!I7-DRE!E7)/ABS(DRE!E7),"") -> 0.22702642 | J7: =IFERROR((DRE!J7-DRE!F7)/ABS(DRE!F7),"") -> 0.21527612 | K7: =IFERROR((DRE!K7-DRE!G7)/ABS(DRE!G7),"") -> 0.24196702 | L7: =IFERROR((DRE!L7-DRE!H7)/ABS(DRE!H7),"") -> 0.19411768 | M7: =IFERROR((DRE!M7-DRE!I7)/ABS(DRE!I7),"") -> 0.16281683 | N7: =IFERROR((DRE!N7-DRE!J7)/ABS(DRE!J7),"") -> 0.16026568 | ... AF7: =IFERROR((DRE!AF7-DRE!AB7)/ABS(DRE!AB7),"") -> 0.13365374
A8: Custo dos serviços | B8: DRE | C8: n.d. | D8: n.d. | E8: n.d. | F8: n.d. | G8: =IFERROR((DRE!G8-DRE!C8)/ABS(DRE!C8),"") -> 0.25398295 | H8: =IFERROR((DRE!H8-DRE!D8)/ABS(DRE!D8),"") -> 0.21228304 | I8: =IFERROR((DRE!I8-DRE!E8)/ABS(DRE!E8),"") -> 0.24849972 | J8: =IFERROR((DRE!J8-DRE!F8)/ABS(DRE!F8),"") -> 0.20171159 | K8: =IFERROR((DRE!K8-DRE!G8)/ABS(DRE!G8),"") -> 0.074675647 | L8: =IFERROR((DRE!L8-DRE!H8)/ABS(DRE!H8),"") -> 0.10272533 | M8: =IFERROR((DRE!M8-DRE!I8)/ABS(DRE!I8),"") -> 0.08760595 | N8: =IFERROR((DRE!N8-DRE!J8)/ABS(DRE!J8),"") -> 0.25795288 | ... AF8: =IFERROR((DRE!AF8-DRE!AB8)/ABS(DRE!AB8),"") -> 0.13363614
A9: Lucro bruto | B9: DRE | C9: n.d. | D9: n.d. | E9: n.d. | F9: n.d. | G9: =IFERROR((DRE!G9-DRE!C9)/ABS(DRE!C9),"") -> 0.31363239 | H9: =IFERROR((DRE!H9-DRE!D9)/ABS(DRE!D9),"") -> 0.3061969 | I9: =IFERROR((DRE!I9-DRE!E9)/ABS(DRE!E9),"") -> 0.19604227 | J9: =IFERROR((DRE!J9-DRE!F9)/ABS(DRE!F9),"") -> 0.23876705 | K9: =IFERROR((DRE!K9-DRE!G9)/ABS(DRE!G9),"") -> 0.51973533 | L9: =IFERROR((DRE!L9-DRE!H9)/ABS(DRE!H9),"") -> 0.32707693 | M9: =IFERROR((DRE!M9-DRE!I9)/ABS(DRE!I9),"") -> 0.27609948 | N9: =IFERROR((DRE!N9-DRE!J9)/ABS(DRE!J9),"") -> -0.0038474849 | ... AF9: =IFERROR((DRE!AF9-DRE!AB9)/ABS(DRE!AB9),"") -> 0.13367004
A10: Despesas operacionais | B10: DRE | C10: n.d. | D10: n.d. | E10: n.d. | F10: n.d. | G10: =IFERROR((DRE!G13-DRE!C13)/ABS(DRE!C13),"") -> 0.015478967 | H10: =IFERROR((DRE!H13-DRE!D13)/ABS(DRE!D13),"") -> -0.053168351 | I10: =IFERROR((DRE!I13-DRE!E13)/ABS(DRE!E13),"") -> 0.073945765 | J10: =IFERROR((DRE!J13-DRE!F13)/ABS(DRE!F13),"") -> -0.011574964 | K10: =IFERROR((DRE!K13-DRE!G13)/ABS(DRE!G13),"") -> 0.10347812 | L10: =IFERROR((DRE!L13-DRE!H13)/ABS(DRE!H13),"") -> 0.28734811 | M10: =IFERROR((DRE!M13-DRE!I13)/ABS(DRE!I13),"") -> 0.21436318 | N10: =IFERROR((DRE!N13-DRE!J13)/ABS(DRE!J13),"") -> 0.20519659 | ... AF10: =IFERROR((DRE!AF13-DRE!AB13)/ABS(DRE!AB13),"") -> 0.17744994
A11: EBIT | B11: DRE | C11: n.d. | D11: n.d. | E11: n.d. | F11: n.d. | G11: =IFERROR((DRE!G14-DRE!C14)/ABS(DRE!C14),"") -> 1.0873217 | H11: =IFERROR((DRE!H14-DRE!D14)/ABS(DRE!D14),"") -> 0.92226993 | I11: =IFERROR((DRE!I14-DRE!E14)/ABS(DRE!E14),"") -> 0.34136981 | J11: =IFERROR((DRE!J14-DRE!F14)/ABS(DRE!F14),"") -> 1.0811713 | K11: =IFERROR((DRE!K14-DRE!G14)/ABS(DRE!G14),"") -> 1.0452322 | L11: =IFERROR((DRE!L14-DRE!H14)/ABS(DRE!H14),"") -> 0.36062442 | M11: =IFERROR((DRE!M14-DRE!I14)/ABS(DRE!I14),"") -> 0.33493223 | N11: =IFERROR((DRE!N14-DRE!J14)/ABS(DRE!J14),"") -> -0.33793524 | ... AF11: =IFERROR((DRE!AF14-DRE!AB14)/ABS(DRE!AB14),"") -> 0.1107152
A12: EBITDA | B12: DRE | C12: n.d. | D12: n.d. | E12: n.d. | F12: n.d. | G12: =IFERROR((DRE!G30-DRE!C30)/ABS(DRE!C30),"") -> 1.044511 | H12: =IFERROR((DRE!H30-DRE!D30)/ABS(DRE!D30),"") -> 0.8917347 | I12: =IFERROR((DRE!I30-DRE!E30)/ABS(DRE!E30),"") -> 0.33418873 | J12: =IFERROR((DRE!J30-DRE!F30)/ABS(DRE!F30),"") -> 1.0278103 | K12: =IFERROR((DRE!K30-DRE!G30)/ABS(DRE!G30),"") -> 1.0223466 | L12: =IFERROR((DRE!L30-DRE!H30)/ABS(DRE!H30),"") -> 0.36218329 | M12: =IFERROR((DRE!M30-DRE!I30)/ABS(DRE!I30),"") -> 0.35881743 | N12: =IFERROR((DRE!N30-DRE!J30)/ABS(DRE!J30),"") -> -0.29449951 | ... AF12: =IFERROR((DRE!AF30-DRE!AB30)/ABS(DRE!AB30),"") -> 0.11373964
A13: Despesa de juros | B13: DRE | C13: n.d. | D13: n.d. | E13: n.d. | F13: n.d. | G13: =IFERROR((DRE!G15-DRE!C15)/ABS(DRE!C15),"") -> 0.35825543 | H13: =IFERROR((DRE!H15-DRE!D15)/ABS(DRE!D15),"") -> 0.24414436 | I13: =IFERROR((DRE!I15-DRE!E15)/ABS(DRE!E15),"") -> 0.22668368 | J13: =IFERROR((DRE!J15-DRE!F15)/ABS(DRE!F15),"") -> 0.10902638 | K13: =IFERROR((DRE!K15-DRE!G15)/ABS(DRE!G15),"") -> 0.056262664 | L13: =IFERROR((DRE!L15-DRE!H15)/ABS(DRE!H15),"") -> 0.011477603 | M13: =IFERROR((DRE!M15-DRE!I15)/ABS(DRE!I15),"") -> -0.033742814 | N13: =IFERROR((DRE!N15-DRE!J15)/ABS(DRE!J15),"") -> -0.039338493 | ... AF13: =IFERROR((DRE!AF15-DRE!AB15)/ABS(DRE!AB15),"") -> -0.038127775
A14: Lucro líquido | B14: DRE | C14: n.d. | D14: n.d. | E14: n.d. | F14: n.d. | G14: =IFERROR((DRE!G19-DRE!C19)/ABS(DRE!C19),"") -> 1.0609297 | H14: =IFERROR((DRE!H19-DRE!D19)/ABS(DRE!D19),"") -> 1.6609865 | I14: =IFERROR((DRE!I19-DRE!E19)/ABS(DRE!E19),"") -> 0.18749812 | J14: =IFERROR((DRE!J19-DRE!F19)/ABS(DRE!F19),"") -> -0.076348025 | K14: =IFERROR((DRE!K19-DRE!G19)/ABS(DRE!G19),"") -> 1.4069869 | L14: =IFERROR((DRE!L19-DRE!H19)/ABS(DRE!H19),"") -> 0.87867331 | M14: =IFERROR((DRE!M19-DRE!I19)/ABS(DRE!I19),"") -> 0.83432281 | N14: =IFERROR((DRE!N19-DRE!J19)/ABS(DRE!J19),"") -> 0.12039524 | ... AF14: =IFERROR((DRE!AF19-DRE!AB19)/ABS(DRE!AB19),"") -> 0.088308649
A15: Fluxo de caixa operacional | B15: DFC | C15: n.d. | D15: n.d. | E15: n.d. | F15: n.d. | G15: =IFERROR((DFC!G7-DFC!C7)/ABS(DFC!C7),"") -> 1.6843409 | H15: =IFERROR((DFC!H7-DFC!D7)/ABS(DFC!D7),"") -> 2.9146084 | I15: =IFERROR((DFC!I7-DFC!E7)/ABS(DFC!E7),"") -> 3.5184857 | J15: =IFERROR((DFC!J7-DFC!F7)/ABS(DFC!F7),"") -> 0.9058315 | K15: =IFERROR((DFC!K7-DFC!G7)/ABS(DFC!G7),"") -> 1.9904968 | L15: =IFERROR((DFC!L7-DFC!H7)/ABS(DFC!H7),"") -> -1.0612453 | M15: =IFERROR((DFC!M7-DFC!I7)/ABS(DFC!I7),"") -> -0.93481442 | N15: =IFERROR((DFC!N7-DFC!J7)/ABS(DFC!J7),"") -> -1.9292376 | ... AF15: =IFERROR((DFC!AF7-DFC!AB7)/ABS(DFC!AB7),"") -> -0.28038533
A16: Fluxo de caixa livre | B16: DFC | C16: n.d. | D16: n.d. | E16: n.d. | F16: n.d. | G16: =IFERROR((DFC!G9-DFC!C9)/ABS(DFC!C9),"") -> 1.3677973 | H16: =IFERROR((DFC!H9-DFC!D9)/ABS(DFC!D9),"") -> 2.5417048 | I16: =IFERROR((DFC!I9-DFC!E9)/ABS(DFC!E9),"") -> 3.1091081 | J16: =IFERROR((DFC!J9-DFC!F9)/ABS(DFC!F9),"") -> 0.81778313 | K16: =IFERROR((DFC!K9-DFC!G9)/ABS(DFC!G9),"") -> 3.3006665 | L16: =IFERROR((DFC!L9-DFC!H9)/ABS(DFC!H9),"") -> -1.1935197 | M16: =IFERROR((DFC!M9-DFC!I9)/ABS(DFC!I9),"") -> -1.073615 | N16: =IFERROR((DFC!N9-DFC!J9)/ABS(DFC!J9),"") -> -0.99020026 | ... AF16: =IFERROR((DFC!AF9-DFC!AB9)/ABS(DFC!AB9),"") -> -0.32734019
A17: Pagamentos de conteúdo | B17: DFC | C17: n.d. | D17: n.d. | E17: n.d. | F17: n.d. | G17: =IFERROR((DFC!G15-DFC!C15)/ABS(DFC!C15),"") -> 0.09891732 | H17: =IFERROR((DFC!H15-DFC!D15)/ABS(DFC!D15),"") -> -0.24490099 | I17: =IFERROR((DFC!I15-DFC!E15)/ABS(DFC!E15),"") -> -0.27256755 | J17: =IFERROR((DFC!J15-DFC!F15)/ABS(DFC!F15),"") -> -0.15845757 | K17: =IFERROR((DFC!K15-DFC!G15)/ABS(DFC!G15),"") -> -0.0029441986 | L17: =IFERROR((DFC!L15-DFC!H15)/ABS(DFC!H15),"") -> 0.63166296 | M17: =IFERROR((DFC!M15-DFC!I15)/ABS(DFC!I15),"") -> 0.7582658 | N17: =IFERROR((DFC!N15-DFC!J15)/ABS(DFC!J15),"") -> 0.7030296 | ... AF17: =IFERROR((DFC!AF15-DFC!AB15)/ABS(DFC!AB15),"") -> 0.28460981
A18: Caixa e equivalentes | B18: BP | C18: n.d. | D18: n.d. | E18: n.d. | F18: n.d. | G18: =IFERROR((BP!G7-BP!C7)/ABS(BP!C7),"") -> 0.53853854 | H18: =IFERROR((BP!H7-BP!D7)/ABS(BP!D7),"") -> 0.42943544 | I18: =IFERROR((BP!I7-BP!E7)/ABS(BP!E7),"") -> 0.89230145 | J18: =IFERROR((BP!J7-BP!F7)/ABS(BP!F7),"") -> 0.6350808 | K18: =IFERROR((BP!K7-BP!G7)/ABS(BP!G7),"") -> 0.63119065 | L18: =IFERROR((BP!L7-BP!H7)/ABS(BP!H7),"") -> 0.087272523 | M18: =IFERROR((BP!M7-BP!I7)/ABS(BP!I7),"") -> -0.10315415 | N18: =IFERROR((BP!N7-BP!J7)/ABS(BP!J7),"") -> -0.26539915 | ... AF18: =IFERROR((BP!AF7-BP!AB7)/ABS(BP!AB7),"") -> 0.11272855
A19: Ativo circulante | B19: BP | C19: n.d. | D19: n.d. | E19: n.d. | F19: n.d. | G19: =IFERROR((BP!G10-BP!C10)/ABS(BP!C10),"") -> 0.54663584 | H19: =IFERROR((BP!H10-BP!D10)/ABS(BP!D10),"") -> 0.45719078 | I19: =IFERROR((BP!I10-BP!E10)/ABS(BP!E10),"") -> 0.84439308 | J19: =IFERROR((BP!J10-BP!F10)/ABS(BP!F10),"") -> 0.57992614 | K19: =IFERROR((BP!K10-BP!G10)/ABS(BP!G10),"") -> 0.56759481 | L19: =IFERROR((BP!L10-BP!H10)/ABS(BP!H10),"") -> 0.12145261 | M19: =IFERROR((BP!M10-BP!I10)/ABS(BP!I10),"") -> -0.041794518 | N19: =IFERROR((BP!N10-BP!J10)/ABS(BP!J10),"") -> -0.1733075 | ... AF19: =IFERROR((BP!AF10-BP!AB10)/ABS(BP!AB10),"") -> 0.15510552
A20: Ativos de conteúdo | B20: BP | C20: n.d. | D20: n.d. | E20: n.d. | F20: n.d. | G20: =IFERROR((BP!G11-BP!C11)/ABS(BP!C11),"") -> 0.20959113 | H20: =IFERROR((BP!H11-BP!D11)/ABS(BP!D11),"") -> 0.14624146 | I20: =IFERROR((BP!I11-BP!E11)/ABS(BP!E11),"") -> 0.07887409 | J20: =IFERROR((BP!J11-BP!F11)/ABS(BP!F11),"") -> 0.035886494 | K20: =IFERROR((BP!K11-BP!G11)/ABS(BP!G11),"") -> 0.030755745 | L20: =IFERROR((BP!L11-BP!H11)/ABS(BP!H11),"") -> 0.084933932 | M20: =IFERROR((BP!M11-BP!I11)/ABS(BP!I11),"") -> 0.1558349 | N20: =IFERROR((BP!N11-BP!J11)/ABS(BP!J11),"") -> 0.21807437 | ... AF20: =IFERROR((BP!AF11-BP!AB11)/ABS(BP!AB11),"") -> 0.054478405
A21: Ativo total | B21: BP | C21: n.d. | D21: n.d. | E21: n.d. | F21: n.d. | G21: =IFERROR((BP!G15-BP!C15)/ABS(BP!C15),"") -> 0.28808494 | H21: =IFERROR((BP!H15-BP!D15)/ABS(BP!D15),"") -> 0.23213892 | I21: =IFERROR((BP!I15-BP!E15)/ABS(BP!E15),"") -> 0.24823553 | J21: =IFERROR((BP!J15-BP!F15)/ABS(BP!F15),"") -> 0.15613056 | K21: =IFERROR((BP!K15-BP!G15)/ABS(BP!G15),"") -> 0.14441292 | L21: =IFERROR((BP!L15-BP!H15)/ABS(BP!H15),"") -> 0.10210247 | M21: =IFERROR((BP!M15-BP!I15)/ABS(BP!I15),"") -> 0.10660391 | N21: =IFERROR((BP!N15-BP!J15)/ABS(BP!J15),"") -> 0.13503706 | ... AF21: =IFERROR((BP!AF15-BP!AB15)/ABS(BP!AB15),"") -> 0.10076857
A22: Passivo circulante | B22: BP | C22: n.d. | D22: n.d. | E22: n.d. | F22: n.d. | G22: =IFERROR((BP!G24-BP!C24)/ABS(BP!C24),"") -> 0.14522398 | H22: =IFERROR((BP!H24-BP!D24)/ABS(BP!D24),"") -> 0.099860917 | I22: =IFERROR((BP!I24-BP!E24)/ABS(BP!E24),"") -> 0.093952107 | J22: =IFERROR((BP!J24-BP!F24)/ABS(BP!F24),"") -> 0.13858389 | K22: =IFERROR((BP!K24-BP!G24)/ABS(BP!G24),"") -> 0.013757166 | L22: =IFERROR((BP!L24-BP!H24)/ABS(BP!H24),"") -> 0.027072998 | M22: =IFERROR((BP!M24-BP!I24)/ABS(BP!I24),"") -> 0.013785117 | N22: =IFERROR((BP!N24-BP!J24)/ABS(BP!J24),"") -> 0.087522395 | ... AF22: =IFERROR((BP!AF24-BP!AB24)/ABS(BP!AB24),"") -> 0.35701671
A23: Dívida de longo prazo | B23: BP | C23: n.d. | D23: n.d. | E23: n.d. | F23: n.d. | G23: =IFERROR((BP!G26-BP!C26)/ABS(BP!C26),"") -> 0.37512473 | H23: =IFERROR((BP!H26-BP!D26)/ABS(BP!D26),"") -> 0.21446705 | I23: =IFERROR((BP!I26-BP!E26)/ABS(BP!E26),"") -> 0.25121648 | J23: =IFERROR((BP!J26-BP!F26)/ABS(BP!F26),"") -> 0.071149468 | K23: =IFERROR((BP!K26-BP!G26)/ABS(BP!G26),"") -> 0.048682167 | L23: =IFERROR((BP!L26-BP!H26)/ABS(BP!H26),"") -> -0.02406728 | M23: =IFERROR((BP!M26-BP!I26)/ABS(BP!I26),"") -> -0.048491357 | N23: =IFERROR((BP!N26-BP!J26)/ABS(BP!J26),"") -> -0.070593731 | ... AF23: =IFERROR((BP!AF26-BP!AB26)/ABS(BP!AB26),"") -> -0.18180451
